[Error] Compiler: Found variable _ on right hand side of rule, not bound on
left hand side. Did you mean "?_"?
	Source(rhs-vars-broken-spec.k)
	Location(13,20,13,21)
	13 |	   claim <k> .K => _ </k>
	   .	                   ^
[Error] Compiler: Found variable A on right hand side of rule, not bound on
left hand side. Did you mean "?A"?
	Source(rhs-vars-broken-spec.k)
	Location(15,20,15,21)
	15 |	   claim <k> .K => A </k>
	   .	                   ^
[Warning] Compiler: Variable 'A' defined but not used. Prefix variable name
with underscore if this is intentional.
	Source(rhs-vars-broken-spec.k)
	Location(15,20,15,21)
	15 |	   claim <k> .K => A </k>
	   .	                   ^
[Error] Compiler: Had 2 structural errors.
Traceback (most recent call last):
  File "/home/dev/src/pyk/src/pyk/ktool/kprove.py", line 105, in _kprove
    return run_process(run_args, logger=_LOGGER, env=env, check=check)
  File "/home/dev/src/pyk/src/pyk/utils.py", line 451, in run_process
    res.check_returncode()
  File "/usr/lib/python3.10/subprocess.py", line 457, in check_returncode
    raise CalledProcessError(self.returncode, self.args, self.stdout,
subprocess.CalledProcessError: Command '('kprove', 'rhs-vars-broken-spec.k', '--definition', 'demo-kompiled', '--output', 'json', '--type-inference-mode', 'checked', '--dry-run', '--emit-json-spec', '/tmp/tmpbwepg6dd')' returned non-zero exit status 113.

The above exception was the direct cause of the following exception:

Traceback (most recent call last):
  File "<string>", line 1, in <module>
  File "/home/dev/src/pyk/src/pyk/__main__.py", line 90, in main
    execute(options)
  File "/home/dev/src/pyk/src/pyk/__main__.py", line 252, in exec_prove
    proofs = kprove.prove_rpc(options=options)
  File "/home/dev/src/pyk/src/pyk/ktool/kprove.py", line 380, in prove_rpc
    all_claims = self.get_claims(
  File "/home/dev/src/pyk/src/pyk/ktool/kprove.py", line 425, in get_claims
    flat_module_list = self.get_claim_modules(
  File "/home/dev/src/pyk/src/pyk/ktool/kprove.py", line 400, in get_claim_modules
    _kprove(
  File "/home/dev/src/pyk/src/pyk/ktool/kprove.py", line 107, in _kprove
    raise RuntimeError(
RuntimeError: ('Command kprove exited with code 113 for: rhs-vars-broken-spec.k', '', None)
